Workbook
Name AnswerProductTable: '[1]V Exact (an)'!$A$12:$D$19
Name Bats: [2]VL_exact!$A$4:$D$13
Name Bats: [2]VL_exact!$A$4:$D$13
Name Bats: [2]VL_exact!$A$4:$D$13
Name Bats: VL_exact!$A$15:$D$24
Name Bats1: [2]VL_exact!$A$4:$D$13
Name BoomLookup: '[3]VLOOKUP(2)'!$A$42:$D$47
Name CLT: VLOOKUP_T!$A$15:$C$18
Name Commission: VLOOKUP_T!$A$2:$B$5
Name CommLookupTable: '[3]Assumption Sheet'!$A$9:$B$12
Name Cricketbats: VL_exact!$A$14:$D$24
Name GradeTable: '[4]V(2)'!$A$8:$F$12
Name RateIncreaseData: [3]Assumptions!$A$3:$E$8
Name s: '[5]Y(203)-SUMIF'!$C$14:$C$24
Name Shipping3Tables: '[4]I(3)'!$C$11:$F$15,'[4]I(3)'!$C$20:$F$24,'[4]I(3)'!$C$29:$F$33
Name sr: '[5]Y(203)-SUMIF'!$B$14:$B$24
Name Table1: [4]Table1!$A$3:$B$7
Name Table2: [4]Table2!$A$3:$B$7
Name Table3: [4]Table3!$A$3:$B$7

Sheet Assumption Sheet
A1: Assumptions for 'WorkbookWorksheetR' sheet and 'VLOOKUP(1)' sheet
A2: SalesRep | B2: Commission Rates
A3: Noddy | B3: 0.025
A4: Raju | B4: 0.0305
A5: Bholu | B5: 0.0195
A7: Assumptions for 'VLOOKUP(2)' sheet
A8: Sales | B8: Commission Rate
A9: 0 | B9: 0
A10: 1500 | B10: 0.05
A11: 5000 | B11: 0.065
A12: 6000 | B12: 0.0755

Sheet VL_exact
A1: VLOOKUP Delivers a value to a cell
A2: VlookUP is not case sensitive
A3: Exact Match: means VLOOKUP starts at first item in first column and looks through column at each item until it finds an exact match.
A4: If there are duplicates, it only finds the first one.
A5: If it can't find a match, it returns an #N/A error.
A6: 1st column is where VLOOKUP "looks" to figure out what row in the table has the value it wants
A7: Tell VLOOKUP what value it should look up = 1st argument
A8: Tell VLOOKUP where the table is = 2nd argument
A9: Tell VLOOKUP what column holds the value you want to return to the cell = 3rd argument
A10: Tell VLOOKUP whether you are doing exact ( 0 ) or approximate (leave argument blank) match = 4th argument
A12: Top 10 cricketing bats in the world
A14: Cricket Bats | B14: Part Number | C14: Hitting Range (meters) | D14: Price
A15: Kookaburra Kahuna | B15: 1000-165-B100 | C15: 40 | D15: 25000 | F15: VLOOKUP IS MAGICAL
A16: Adidas Incurza | B16: 1001-540-C101 | C16: 35 | D16: 23000
A17: Gray-Nicolls Viper | B17: 1002-394-M102 | C17: 33 | D17: 22700
A18: GM Icon | B18: 1003-307-Q103 | C18: 32 | D18: 21900
A19: SG Cobra select | B19: 1004-848-S104 | C19: 31 | D19: 20987
A20: Puma Ballistic | B20: 1005-155-S105 | C20: 30 | D20: 19876
A21: SS Ton GLADIATOR | B21: 1006-552-T106 | C21: 29 | D21: 19654
A22: Kookaburra Angry Beast | B22: 1007-634-O107 | C22: 28 | D22: 18765
A23: Reebok Blast | B23: 1009-987-B098 | C23: 25 | D23: 16000
A24: Spartan CG Authority | B24: 1007-567-C987 | C24: 20 | D24: 15000
A26: Exact Match: Linear search (top to bottom). If there are duplicates, it only finds the first one. If it can't find a match, it returns an #N?A error.
A27: Cricket Bats | B27: Price | C27: Units | D27: Total
A28: Adidas Incurza | B28: =VLOOKUP(A28,A15:D24,4,FALSE) -> 23000 | C28: 3 | D28: =C28*B28 -> 69000
A30: VLOOKUP #N/A and IFERROR or IF
A31: Cricket Bats | B31: Part Number
A32: Reebok Blats | B32: =IFERROR(VLOOKUP(A32,Cricketbats,2,0),"ERROR!!") -> ERROR!! | C32: Used IFERROR
A34: VLOOKUP and Data Validation
A35: Cricket Bats | B35: Range
A36: GM Icon | B36: =VLOOKUP(A36,Bats,3,0) -> 32 | C36: Select name of bat from drop down list to get Hitting range
A38: VLOOKUP with Named Range
A39: Cricket Bats | B39: Price
A40: Kookaburra Angry Beast | B40: =VLOOKUP(A40,Cricketbats,4,0) -> 18765
A42: VLOOKUP as Formula Element
A43: Cricket Bats | B43: Units | C43: Total
A44: Kookaburra Angry Beast | B44: 3 | C44: =VLOOKUP(A44,Bats,4,FALSE)*B44 -> 56295 | F44: 56295 | G44: Paste values and source formatting
A46: Invoive Example:
A47: Product | B47: Units | C47: Price | D47: Total
A48: Adidas Incurza | B48: 5 | C48: =IF(ISNA(VLOOKUP(A48,Bats,4,0)),"",VLOOKUP(A48,Bats,4,0)) -> 23000 | D48: =IFERROR(C48*B48," ") -> 115000
...

Sheet V Exact
A1: VLOOKUP Delivers a value to a cell
A2: VlookUP is not case sensitive
A3: Exact Match: means VLOOKUP starts at first item in first column and looks through column at each item until it finds an exact match.
A4: If there are duplicates, it only finds the first one.
A5: If it can't find a match, it returns an #N/A error.
A6: 1st column is where VLOOKUP "looks" to figure out what row in the table has the value it wants
A7: Tell VLOOKUP what value it should look up = 1st argument
A8: Tell VLOOKUP where the table is = 2nd argument
A9: Tell VLOOKUP what column holds the value you want to return to the cell = 3rd argument
A10: Tell VLOOKUP whether you are doing exact ( 0 ) or approximate (leave argument blank) match = 4th argument
A12: Boomerang | B12: Part Number | C12: Flight Range (meters) | D12: Price
A13: Bellen | B13: 1000-165-B100 | C13: 25 | D13: 26.95
A14: Carlota | B14: 1001-540-C101 | C14: 20 | D14: 28.95
A15: Majestic Beaut | B15: 1002-394-M102 | C15: 35 | D15: 31.95
A16: Quad | B16: 1003-307-Q103 | C16: 20 | D16: 35.95
A17: Sunshine | B17: 1004-848-S104 | C17: 30 | D17: 18.95
A18: Sunset | B18: 1005-155-S105 | C18: 40 | D18: 20.95
A19: Tri-Fly | B19: 1006-552-T106 | C19: 1 | D19: 4.95
A20: Outdoor Tri-Fly | B20: 1007-634-O107 | C20: 5 | D20: 8.95
A22: Exact Match: Linear search (top to bottom). If there are duplicates, it only finds the first one. If it can't find a match, it returns an #N?A error.
A23: Boomerang | B23: Price | C23: Units | D23: Total
A24: Quad | B24: =VLOOKUP(A24,A13:D20,4,FALSE) -> 35.95 | C24: 3 | D24: =B24*C24 -> 107.85
A26: VLOOKUP #N/A and IFERROR or IF
A27: Boomerang | B27: Part Number
A28: Bellen | F28: =IF(ISNA(VLOOKUP(A28,A13:D20,2,0)),"Not In List",VLOOKUP(A28,A13:D20,2,0)) -> 1000-165-B100
A30: VLOOKUP and Data Validation | C30: Alt, D, L = Data Validation
A31: Boomerang | B31: Range
A32: Majestic Beaut
A34: VLOOKUP with Named Range
A35: Boomerang | B35: Price | C35: Name Box = left side of formula bar
A36: Carlota | C36: Ctrl + F3 = Name Manager | E36: F2 and Edit Mode:
E37: Edit = Arrow Keys move through formula
A38: VLOOKUP as Formula Element | E38: Enter = Arrow Keys can put cell references in formula
A39: Boomerang | B39: Units | C39: Total | E39: Point = Arrow Keys are putting cell references in formula (dancing ants are dancing).
A40: Majestic Beaut | B40: 3
A42: Invoive Example:
A43: Product | B43: Units | C43: Price | D43: Total
A44: Carlota | B44: 5
A45: Sunshine | B45: 2
A46: Majestic Beaut | B46: 3
...

Sheet BB
A1: Last Name | B1: First Name | C1: Username | D1: Student ID | E1: Last Access | F1: Final
A2: . | B2: Praveen Raj V | C2: pr450 | D2: 1510110274 | E2: 43481.535 | F2: 91 | G2: =F2/0 -> #DIV/0!
A3: AGARWAL | B3: BHAVYA | C3: ba751 | D3: 1610110092 | E3: 43490.527 | F3: 98 | G3: =F3/0 -> #DIV/0!
A4: Arora | B4: Kabir | C4: ka682 | D4: 1710110165 | E4: 43490.532 | F4: 95 | G4: =F4/0 -> #DIV/0!
A5: Arora | B5: Shaurya | C5: sa194 | D5: 1610110501 | E5: 43490.524 | F5: 92 | G5: =F5/0 -> #DIV/0!
A6: Chauhan | B6: Devansh | C6: dc472 | D6: 1510110119 | F6: 98 | G6: =F6/0 -> #DIV/0!
A7: Chauhan | B7: Muskaan | C7: mc762 | D7: 1710110222 | E7: 43490.519 | F7: 94 | G7: =F7/0 -> #DIV/0!
A8: Chhabra | B8: Urja | C8: uc464 | D8: 1610110509 | E8: 43474.509 | F8: 91 | G8: =F8/0 -> #DIV/0!
A9: Dave | B9: Arpit | C9: ad933 | D9: 1510110086 | E9: 43490.522 | F9: 91 | G9: =F9/0 -> #DIV/0!
A10: DWIVEDI | B10: ADITYA | C10: ad792 | D10: 1610110008 | E10: 43490.523 | F10: 91 | G10: =F10/0 -> #DIV/0!
A11: Gottumukkala | B11: Subhash | C11: sg127 | D11: 1610110382 | E11: 43490.518 | F11: 90 | G11: =F11/0 -> #DIV/0!
A12: Gupta | B12: Abhinav | C12: ag569 | D12: 1710110010 | E12: 43490.522 | F12: 99 | G12: =F12/0 -> #DIV/0!
A13: Gupta | B13: Mukul | C13: mg424 | D13: 1610110486 | E13: 43490.525 | F13: 96 | G13: =F13/0 -> #DIV/0!
A14: Gupta | B14: Saurabh | C14: sg184 | D14: 1610110343 | E14: 43490.532 | F14: 91
A15: Gupta | B15: Vedansh | C15: vg452 | D15: 1610110429 | E15: 43490.532 | F15: 91
A16: Handa | B16: Bhavini | C16: bh934 | D16: 1610110473 | E16: 43490.522 | F16: 92
A17: J | B17: ABHIJIT | C17: aj448 | D17: 1610110003 | E17: 43490.532 | F17: 94
A18: Jain | B18: Akshat | C18: aj648 | D18: 1710110038 | E18: 43490.533 | F18: 96
A19: Jalota | B19: Sargam | C19: sj871 | D19: 1610110336 | E19: 43490.525 | F19: 97
A20: Jay | B20: Ritwik | C20: rj327 | D20: 1510110310 | E20: 43490.531 | F20: 100
A21: Joshi | B21: Akshara | C21: aj897 | D21: 1610110051 | E21: 43490.532 | F21: 96
A22: Kanhe | B22: Paritosh | C22: pn596 | D22: 1510110261 | E22: 43490.523 | F22: 93
A23: Kapoor | B23: Garima | C23: gk846 | D23: 1610110481 | E23: 43490.529 | F23: 94
A24: KATIYAR | B24: VARUN | C24: vk129 | D24: 1610110419 | E24: 43490.531 | F24: 96
A25: Kilaparthi | B25: Venkata Sai | C25: vk677 | D25: 1710110383 | E25: 43490.532 | F25: 98
... A44: VUNNAVA | B44: BALAJI | C44: bv808 | D44: 1610110089 | E44: 43490.52 | F44: 95

Sheet ERP
A1: Notify | B1: Campus ID | C1: Name | D1: Grade Basis | E1: Units | F1: Program and Plan | G1: Level | H1: Marks
B2: 1610110051 | C2: .,Akshara | D2: Graded | E2: 1.5 | F2: Bachelor of Science (Research) - Mathematics | G2: 3rd Year | H2: =VLOOKUP(B2,BB!$D$1:$G$44,3,0) -> 96
B3: 1610110092 | C3: AGGARWAL,BHAVYA | D3: Graded | E3: 1.5 | F3: Bachelor of Technology - Electrical & Electronics Engg | G3: 3rd Year | H3: =VLOOKUP(B3,BB!$D$1:$G$44,3,0) -> 98
B4: 1710110165 | C4: Arora,Kabir Kanha | D4: Graded | E4: 1.5 | F4: Bachelor of Technology - Computer Science & Engineering | G4: 2nd Year | H4: =VLOOKUP(B4,BB!$D$1:$G$44,3,0) -> 95
B5: 1610110501 | C5: Arora,Shaurya | D5: Graded | E5: 1.5 | F5: Bachelor of Management Studies - Bachelor of Management Studies | G5: 3rd Year | H5: =VLOOKUP(B5,BB!$D$1:$G$44,3,0) -> 92
B6: 1510110119 | C6: Chauhan,Devansh | D6: Graded | E6: 1.5 | F6: Bachelor of Technology - Computer Science & Engineering | G6: 4th Year | H6: =VLOOKUP(B6,BB!$D$1:$G$44,3,0) -> 98
B7: 1710110222 | C7: Chauhan,Muskaan | D7: Graded | E7: 1.5 | F7: Bachelor of Science (Research) - Economics | G7: 2nd Year | H7: =VLOOKUP(B7,BB!$D$1:$G$44,3,0) -> 94
B8: 1610110509 | C8: Chhabra,Urja | D8: Graded | E8: 1.5 | F8: Bachelor of Management Studies - Bachelor of Management Studies | G8: 3rd Year | H8: =VLOOKUP(B8,BB!$D$1:$G$44,3,0) -> 91
B9: 1610110008 | C9: DWIVEDI,ADITYA | D9: Graded | E9: 1.5 | F9: Bachelor of Technology - Electronics and Comm Engg | G9: 3rd Year | H9: =VLOOKUP(B9,BB!$D$1:$G$44,3,0) -> 91
B10: 1510110086 | C10: Dave,Arpit | D10: Graded | E10: 1.5 | F10: Bachelor of Technology - Electronics and Comm Engg | G10: 4th Year | H10: =VLOOKUP(B10,BB!$D$1:$G$44,3,0) -> 91
B11: 1610110382 | C11: Gottumukkala,Subhash | D11: Graded | E11: 1.5 | F11: Bachelor of Technology - Civil Engineering | G11: 3rd Year | H11: =VLOOKUP(B11,BB!$D$1:$G$44,3,0) -> 90
B12: 1710110010 | C12: Gupta,Abhinav | D12: Graded | E12: 1.5 | F12: Bachelor of Management Studies - Bachelor of Management Studies | G12: 2nd Year | H12: =VLOOKUP(B12,BB!$D$1:$G$44,3,0) -> 99
B13: 1610110486 | C13: Gupta,Mukul | D13: Graded | E13: 1.5 | F13: Bachelor of Management Studies - Bachelor of Management Studies | G13: 3rd Year | H13: =VLOOKUP(B13,BB!$D$1:$G$44,3,0) -> 96
... B44: 1610110089 | C44: VUNNAVA,BALAJI | D44: Graded | E44: 1.5 | F44: Bachelor of Technology - Electrical & Electronics Engg | G44: 3rd Year | H44: =VLOOKUP(B44,BB!$D$1:$G$44,3,0) -> 95

Sheet VLOOKUP_T
A1: Example 1: Lookup Exact Value
A2: SalesRep | B2: Commission Rate | D2: SalesRep | E2: Sales | F2: Commission Rate | G2: Commission | H2: 1 Formula Commission
A3: Noddy | B3: 0.05 | D3: Noddy | E3: 5356 | F3: =VLOOKUP(D3,Commission,2,0) -> 0.05 | G3: =E3*F3 -> 267.8 | H3: =VLOOKUP(D3,Commission,2,0)*E3 -> 267.8
A4: Raju | B4: 0.065 | D4: Raju | E4: 6083 | F4: =VLOOKUP(D4,Commission,2,0) -> 0.065 | G4: =E4*F4 -> 395.395 | H4: =VLOOKUP(D4,Commission,2,0)*E4 -> 395.395
A5: Bholu | B5: 0.0755 | D5: Bholu | E5: 5899 | F5: =VLOOKUP(D5,Commission,2,0) -> 0.0755 | G5: =E5*F5 -> 445.3745 | H5: =VLOOKUP(D5,Commission,2,0)*E5 -> 445.3745
D6: Noddy | E6: 3316 | F6: =VLOOKUP(D6,Commission,2,0) -> 0.05 | G6: =E6*F6 -> 165.8 | H6: =VLOOKUP(D6,Commission,2,0)*E6 -> 165.8
D7: Raju | E7: 2014 | F7: =VLOOKUP(D7,Commission,2,0) -> 0.065 | G7: =E7*F7 -> 130.91 | H7: =VLOOKUP(D7,Commission,2,0)*E7 -> 130.91
D8: Bholu | E8: 3116 | F8: =VLOOKUP(D8,Commission,2,0) -> 0.0755 | G8: =E8*F8 -> 235.258 | H8: =VLOOKUP(D8,Commission,2,0)*E8 -> 235.258
D9: Raju | E9: 2950 | F9: =VLOOKUP(D9,Commission,2,0) -> 0.065 | G9: =E9*F9 -> 191.75 | H9: =VLOOKUP(D9,Commission,2,0)*E9 -> 191.75
D10: Bholu | E10: 3690 | F10: =VLOOKUP(D10,Commission,2,0) -> 0.0755 | G10: =E10*F10 -> 278.595 | H10: =VLOOKUP(D10,Commission,2,0)*E10 -> 278.595
D11: Raju | E11: 4184 | F11: =VLOOKUP(D11,Commission,2,0) -> 0.065 | G11: =E11*F11 -> 271.96 | H11: =VLOOKUP(D11,Commission,2,0)*E11 -> 271.96
D12: Raju | E12: 6472 | F12: =VLOOKUP(D12,Commission,2,0) -> 0.065 | G12: =E12*F12 -> 420.68 | H12: =VLOOKUP(D12,Commission,2,0)*E12 -> 420.68
A14: Example 2: Lookup Approximate Value
A15: Sales | B15: Commission Rate | C15: Category | D15: SalesRep | E15: Sales | F15: Commission Rate | G15: Commission | H15: 1 Formula Commission
A16: 1500 | B16: 0.05 | C16: =A16&" <= Sales < "&A17 -> 1500 <= Sales < 5000 | D16: Noddy | E16: 5356 | F16: =VLOOKUP(E16,CLT,2,1) -> 0.065 | G16: =E16*F16 -> 348.14 | H16: =VLOOKUP(E16,CLT,2,1)*E16 -> 348.14
A17: 5000 | B17: 0.065 | C17: =A17&" <= Sales < "&A18 -> 5000 <= Sales < 6000 | D17: Raju | E17: 6083 | F17: =VLOOKUP(E17,CLT,2,1) -> 0.0755 | G17: =E17*F17 -> 459.2665 | H17: =VLOOKUP(E17,CLT,2,1)*E17 -> 459.2665
A18: 6000 | B18: 0.0755 | C18: =A18&" <= Sales " -> 6000 <= Sales | D18: Bholu | E18: 5899 | F18: =VLOOKUP(E18,CLT,2,1) -> 0.065 | G18: =E18*F18 -> 383.435 | H18: =VLOOKUP(E18,CLT,2,1)*E18 -> 383.435
D19: Noddy | E19: 3316 | F19: =VLOOKUP(E19,CLT,2,1) -> 0.05 | G19: =E19*F19 -> 165.8 | H19: =VLOOKUP(E19,CLT,2,1)*E19 -> 165.8
D20: Raju | E20: 2014 | F20: =VLOOKUP(E20,CLT,2,1) -> 0.05 | G20: =E20*F20 -> 100.7 | H20: =VLOOKUP(E20,CLT,2,1)*E20 -> 100.7
D21: Bholu | E21: 3116 | F21: =VLOOKUP(E21,CLT,2,1) -> 0.05 | G21: =E21*F21 -> 155.8 | H21: =VLOOKUP(E21,CLT,2,1)*E21 -> 155.8
D22: Raju | E22: 2950 | F22: =VLOOKUP(E22,CLT,2,1) -> 0.05 | G22: =E22*F22 -> 147.5 | H22: =VLOOKUP(E22,CLT,2,1)*E22 -> 147.5
D23: Bholu | E23: 3690 | F23: =VLOOKUP(E23,CLT,2,1) -> 0.05 | G23: =E23*F23 -> 184.5 | H23: =VLOOKUP(E23,CLT,2,1)*E23 -> 184.5
D24: Raju | E24: 4184 | F24: =VLOOKUP(E24,CLT,2,1) -> 0.05 | G24: =E24*F24 -> 209.2 | H24: =VLOOKUP(E24,CLT,2,1)*E24 -> 209.2
D25: Raju | E25: 6472 | F25: =VLOOKUP(E25,CLT,2,1) -> 0.0755 | G25: =E25*F25 -> 488.636 | H25: =VLOOKUP(E25,CLT,2,1)*E25 -> 488.636
A27: Example 3: Lookup Approximate Value from a Different Sheet
D28: SalesRep | E28: Sales | F28: Commission Rate | G28: Commission | H28: 1 Formula Commission | J28: Look at 'Assumption Sheet'
D29: Noddy | E29: 150
D30: Raju | E30: 6083
D31: Bholu | E31: 5899
D32: Noddy | E32: 3316
D33: Raju | E33: 2014
D34: Bholu | E34: 3116
D35: Raju | E35: 2950
D36: Bholu | E36: 3690
D37: Raju | E37: 4184
D38: Raju | E38: 6472
A40: Example 4: Data Validation and Lookup Exact Value from Multiple Columns
A41: Product | B41: Description | C41: Price | D41: Cost | F41: Product | G41: Description | H41: Price | I41: Units | J41: Sales
A42: Boom 1 | B42: 20 Meter Bat | C42: 19 | D42: 14 | F42: Boom 5 | G42: =VLOOKUP($F$42,$A$41:$D$47,COLUMNS($A$41:B41),0) -> 50 Meter Bat | H42: =VLOOKUP($F$42,$A$41:$D$47,COLUMNS($A$41:C41),0) -> 30 | I42: =VLOOKUP($F$42,$A$41:$D$47,COLUMNS($A$41:D41),0) -> 17 | J42: =H42*I42 -> 510
A43: Boom 2 | B43: 25 Meter Bat | C43: 15 | D43: 9
...

Sheet VL_combi
A2: RIGHT extracts a given number of characters from the right
A3: LEFT extracts a given number of characters from the left
A4: MID extracts from the midele giben a starting point and the number of charactesr that you want
A5: SEARCH tells you the position of a text string within a larger text string
A7: Partial Text Lookup: RIGHT
A8: Students ID | B8: Credits required | D8: ID | E8: Credits required
A9: Lakhan-920-M012 | B9: =VLOOKUP(RIGHT(A9,4),D8:E11,2,FALSE) -> 26 | D9: M012 | E9: 26
A10: Mallika-234-E032 | B10: =VLOOKUP(RIGHT(A10,4),D9:E12,2,FALSE) -> 20 | D10: E032 | E10: 20
A11: Shyam-543-H786 | B11: =VLOOKUP(RIGHT(A11,4),D10:E13,2,FALSE) -> 24 | D11: H786 | E11: 24
A13: Partial Text Lookup: LEFT and SEARCH
A14: ID | B14: Credits required | D14: ID | E14: Credits required
A15: Lakhan-920-M012 | B15: =VLOOKUP(LEFT(A15,SEARCH("-",A15,1)-1),D14:E17,2,0) -> 26 | D15: Lakhan | E15: 26
A16: Mallika-234-E032 | B16: =VLOOKUP(LEFT(A16,SEARCH("-",A16,1)-1),D15:E18,2,0) -> 20 | D16: Mallika | E16: 20
A17: Shyam-543-H786 | B17: =VLOOKUP(LEFT(A17,SEARCH("-",A17,1)-1),D16:E19,2,0) -> 24 | D17: Shyam | E17: 24
A20: Partial Text Lookup: MID
A21: Students ID | B21: Credits required | D21: ID | E21: Credits required
A22: Lakhan-920-M012 | B22: =VLOOKUP(_xlfn.NUMBERVALUE(MID(A22,SEARCH("-",A22,1)+1,3)),$D$21:$E$24,2,0) -> 24 | D22: 543 | E22: 26
A23: Mallika-234-E032 | B23: =VLOOKUP(_xlfn.NUMBERVALUE(MID(A23,SEARCH("-",A23,1)+1,3)),$D$21:$E$24,2,0) -> 20 | D23: 234 | E23: 20
A24: Shyam-543-H786 | B24: =VLOOKUP(_xlfn.NUMBERVALUE(MID(A24,SEARCH("-",A24,1)+1,3)),$D$21:$E$24,2,0) -> 26 | D24: 920 | E24: 24
A27: Extract after 2nd dash:
A28: ID | B28: Credits required
A29: Lakhan-920-M012456 | B29: =VLOOKUP(MID(A29,FIND("*",SUBSTITUTE(A29,"-","*",2),1)+1,4),$D$8:$E$11,2,0) -> 26 | D29: Can also use find within find instead of the substitute thing.
A30: Mallika-234-E0327 | B30: =VLOOKUP(MID(A30,FIND("*",SUBSTITUTE(A30,"-","*",2),1)+1,4),$D$8:$E$11,2,0) -> 20 | D30: Or search within search.
A31: Shyam-543-H786 | B31: =VLOOKUP(MID(A31,FIND("*",SUBSTITUTE(A31,"-","*",2),1)+1,4),$D$8:$E$11,2,0) -> 24
A34: ID | B34: Credits required
A35: Lakhan-92032-M012 | B35: =VLOOKUP(MID(A35,FIND("*",SUBSTITUTE(A35,"-","*",2),1)+1,4),$D$8:$E$11,2,0) -> 26
A36: Mallika-2334-E032 | B36: =VLOOKUP(MID(A36,FIND("*",SUBSTITUTE(A36,"-","*",2),1)+1,4),$D$8:$E$11,2,0) -> 20
A37: Shyam-543-H786 | B37: =VLOOKUP(MID(A37,FIND("*",SUBSTITUTE(A37,"-","*",2),1)+1,4),$D$8:$E$11,2,0) -> 24

Sheet V_search
A1: Astrix * means 1 or more characters
A2: Ampersand (Shift + 7) is the join symbol
A5: Partial Text VLOOKUP (Exact Match) with wildcards
A6: Producer | B6: Beer
A7: Great Beer Inc. | B7: Good Beer
A8: Red Hook | B8: Long Hammer
A9: Pyramid Brewery | B9: IPA
A10: Sierra Nevada Brewing Co. | B10: Pale Ale
A12: Partial Text | B12: =A6 -> Producer
A13: Great Beer | B13: =VLOOKUP("*"&A13&"*",A6:B10,2,0) -> Good Beer
A14: Red Hook | B14: =VLOOKUP("*"&A14&"*",A7:B11,2,0) -> Long Hammer
A15: Pyramid | B15: =VLOOKUP("*"&A15&"*",A8:B12,2,0) -> IPA
A16: Sierra Nevada | B16: =VLOOKUP("*"&A16&"*",A9:B13,2,0) -> Pale Ale
A18: Asterisk is a very powerful tool.

Sheet L(1)
A1: =ROW()&")" -> 1) | B1: LOOKUP function was the first lookup function. It was in VisiCalc in 1979.
A2: =ROW()&")" -> 2) | B2: LOOKUP function can do vertical lookup (array argument has more rows than columns), horizontal lookup (array argument has more columns than rows) or lookup where the lookup column (lookup_vector) and the "values to retrieve column" (result_vector) are in different locations.
A3: =ROW()&")" -> 3) | B3: LOOKUP function must have the lookup_vector (1st column for vertical lookup, 1st row for horizontal lookup, or lookup_vector) sorted in ascending order (smallest to biggest).
A4: =ROW()&")" -> 4) | B4: When doing a vertical lookup, LOOKUP always retrieves a value from the last column. When doing a horizontal lookup, LOOKUP always retrieves a value from the last row.
A5: =ROW()&")" -> 5) | B5: LOOKUP only does "approximate match". What it says in help: "LOOKUP looks up the greatest value that does not exceed a specified value anywhere in a table or range."
A6: =ROW()&")" -> 6) | B6: There are two ways to think about how it works: 1) The LOOKUP finds the biggest value that is greater than or equal to the lookup_value 2) The LOOKUP takes the lookup_value in its memory and looks until it sees a value bigger than the lookup_value, then it jumps back to the previous row/column and uses the data from that row/column
A7: =ROW()&")" -> 7) | B7: If the first value in the lookup_vector (1st column for vertical lookup, 1st row for horizontal lookup, or lookup_vector) is bigger than the lookup_value, then LOOKUP returns #N/A (Not Available).
A8: =ROW()&")" -> 8) | B8: If the last value in the lookup_vector lookup_vector (1st column for vertical lookup, 1st row for horizontal lookup, or lookup_vector) is bigger than the lookup_value, then LOOKUP returns the data from the last row.
B10: More rows than columns: LOOKUP does vertical lookup
B11: Commission Table
B12: Sales | C12: Rate | D12: Previous Bracket
B13: 0 | C13: 0 | F13: LOOKUP:
B14: 5000 | C14: 0.005 | D14: 0 | F14: 1) 1st column sorted ascending
B15: 10000 | C15: 0.01 | D15: =(B15-B14)*C14+D14 -> 25 | F15: 2) only does approximate lookup
B16: 20000 | C16: 0.02 | D16: =(B16-B15)*C15+D15 -> 125 | F16: 3) always returns value from last column / row
B17: 30000 | C17: 0.03 | D17: =(B17-B16)*C16+D16 -> 325 | F17: 4) can do V or H Lookup
B18: 50000 | C18: 0.06 | D18: =(B18-B17)*C17+D17 -> 925 | F18: 5) can have 2 vectors
B19: 100000 | C19: 0.1 | D19: =(B19-B18)*C18+D18 -> 3925
B21: Sales | C21: Rate
B22: 100000 | C22: =LOOKUP(B22,B12:D19) -> 3925
B24: More columns than rows LOOKUP does horizontal lookup
B25: Commission Table
B26: {=TRANSPOSE(B12:D19)} -> Sales | C26: 0 | D26: 5000 | E26: 10000 | F26: 20000 | G26: 30000 | H26: 50000 | I26: 100000
B27: Rate | C27: 0 | D27: 0.005 | E27: 0.01 | F27: 0.02 | G27: 0.03 | H27: 0.06 | I27: 0.1
B28: Previous Bracket | C28: 0 | D28: 0 | E28: 25 | F28: 125 | G28: 325 | H28: 925 | I28: 3925
B30: Sales | C30: Rate | E30: LOOKUP:
B31: =B22 -> 100000 | E31: 1) 1st column sorted ascending
E32: 2) only does approximate lookup
E33: 3) always returns value from last column / row
E34: 4) can do V or H Lookup
E35: 5) can have 2 vectors

Sheet L(3)
B1: Look To Left
B2: Lookup can lookup values in one vector and return a value from a different vector (but unlike the alternative INDEX & MATCH, LOOKUP can only lookup an approximate value and the lookup_vector must be sorted in ascending order)
B4: Product | C4: Price | D4: Description
B5: Boom01 | C5: 15 | D5: Flying Range is 10
B6: Boom08 | C6: 110 | D6: Flying Range is 110
B7: Boom09 | C7: 165 | D7: Flying Range is 160
B8: Boom02 | C8: 30 | D8: Flying Range is 20
B9: Boom03 | C9: 40 | D9: Flying Range is 50
B10: Boom04 | C10: 45 | D10: Flying Range is 60
B11: Boom05 | C11: 65 | D11: Flying Range is 70
B12: Boom06 | C12: 69 | D12: Flying Range is 80
B13: Boom07 | C13: 100 | D13: Flying Range is 85
D15: Description | E15: Product
D16: Flying Range is 160
F17: INDEX & MATCH better because you can do exact match
B19: Look in 1 vector and retrieve in another
B20: Names | D20: Hire Date | E20: 39384 | F20: 39617 | G20: 39509 | H20: 39258 | I20: 39308 | J20: 39256 | K20: 39201 | L20: 39160
B21: Name1
B22: Name2 | D22: Names | E22: Hire Date
B23: Name3 | D23: Name2 | F23: Longer to calculate, can't do exact match (must be sorted)
B24: Name4
B25: Name5
B26: Name6
B27: Name7
B28: Name8

Sheet Indian Income Tax
A1: Income Tax Slab | B1: Income Tax Rate
A2: Income upto Rs. 2,50,000 | B2: Nil
A3: Income between Rs. 2,50,001 - Rs. 500,000 | B3: 10% of Income exceeding Rs. 2,50,000
A4: Income between Rs. 500,001 - Rs. 10,00,000 | B4: 20% of Income exceeding Rs. 5,00,000
A5: Income above Rs. 10,00,000 | B5: 30% of Income exceeding Rs. 10,00,000
A8: Lookup Value | B8: Percentage | C8: Tax From Previous Bracket
A9: 0 | B9: 0 | C9: =(A10-A9)*B9 -> 0
A10: 250000 | B10: 0.1
A11: 500000 | B11: 0.2 | C11: =(A11-A10)*B10 -> 25000
A12: 1000000 | B12: 0.3 | C12: =(A12-A11)*B11+C11 -> 125000
B14: 745000
A17: Taxable Earnings | B17: 745000 | D17: Total Tax
A18: =C8 -> Tax From Previous Bracket | B18: =VLOOKUP(B17,A8:C13,3,1) -> 25000 | D18: =B22 -> 74000
A19: Tax Rate | B19: =VLOOKUP(B17,A8:C13,2,1) -> 0.2
A20: Amount already taxed | B20: =VLOOKUP(B17,A8:C13,1,1) -> 500000
A21: Amount to tax in this bracket | B21: =B17-B20 -> 245000
A22: Total Tax | B22: =B18+(B21*B19) -> 74000
