Workbook

Sheet Copyright
A1: Apex Investment - A
A2: Harvard Business School Case #296-028
A3: Case Software #XLS087
A5: Copyright © 2010 President and Fellows of Harvard College. No part of this product may be reproduced, stored in a retrieval system or transmitted in any form or by any means—electronic, mechanical, photocopying, recording or otherwise—without the permission of Harvard Business School.

Sheet Exhibit 6
A1: Exhibit 6 Access Series A Term Sheet: June 4, 1994
A3: Name or Entity | B3: Class of Stock | C3: Number of Shares | D3: Total Percentage Ownership | E3: Price per | F3: Total ownership value | G3: Total Percentage Ownership
A4: Existing Investorsb | B4: Common (Class A and B) | C4: 7931060 | D4: =C4/$C$8 -> 0.61244151 | E4: 7 | F4: =C4*E4 -> 55517420 | G4: =F4/$F$8 -> 0.61244151
A5: New Investors | B5: Series A Preferred | C5: 2500000 | D5: =C5/$C$8 -> 0.19305159 | E5: =F5/C5 -> 7 | F5: 17500000 | G5: =F5/$F$8 -> 0.19305159
B6: Warrants to Purchase Series A Preferred | C6: =C5*0.15 -> 375000 | D6: =C6/$C$8 -> 0.028957739 | E6: 7 | F6: =C6*E6 -> 2625000 | G6: =F6/$F$8 -> 0.028957739
A7: Reserved for Management and Employeesc | B7: Common (Class A and B) | C7: 2143846 | D7: =C7/$C$8 -> 0.16554916 | E7: 7 | F7: =C7*E7 -> 15006922 | G7: =F7/$F$8 -> 0.16554916
A8: Total | C8: 12949906 | D8: =C8/$C$8 -> 1 | F8: =SUM(F4:F7) -> 90649342 | G8: =F8/$F$8 -> 1
A11: aWhile the term sheet was prepared assuming the sale of 2.5 million shares, 2.22 million shares were actually sold.
A12: bIncludes 157,677 shares issued as part of the Fuller Research & Development Company merger, 389,820 shares issued pursuant to restricted stock grants and 1,087,962 shares subject to options granted to Daniel R. Kranzler.
A13: cExcludes 643,600 shares reserved for future grant.

Sheet Exhibit 7
A1: Exhibit 7 Historical Financial Performance and Projected Growth of AccessLine Technologies, Inc.
A3: Consolidated Statements of Operations, Year Ended December 31, 1993
B5: 1993 | C5: Common size PnL
A6: Revenue
A7: Systems revenue | B7: 7551090 | C7: =B7/$B$9 -> 0.90326323
A8: Licensing and maintenance | B8: 808699 | C8: =B8/$B$9 -> 0.096736772
A9: Total revenue | B9: 8359789 | C9: =B9/$B$9 -> 1
A11: Cost of systems | B11: 2815292 | C11: =B11/$B$9 -> 0.33676592
A12: Gross margin | B12: 5544497 | C12: =B12/$B$9 -> 0.66323408
A14: Operating expenses
A15: Sales, general and administrative | B15: 4985320 | C15: =B15/$B$9 -> 0.59634519
A16: Engineering, research and development | B16: 1421099 | C16: =B16/$B$9 -> 0.16999221
A17: Total operating expenses | B17: 6406419 | C17: =B17/$B$9 -> 0.7663374
A19: Operating loss | B19: -861922 | C19: =B19/$B$9 -> -0.10310332
A21: Other income, net | B21: 12348 | C21: =B21/$B$9 -> 0.0014770708
A23: Net loss | B23: -849574 | C23: =B23/$B$9 -> -0.10162625
A25: Net loss per share | B25: -0.1
A27: Weighted average common share outstanding | B27: 8751598
A31: Consolidated Balance Sheet, December 31, 1993
A33: Assets | B33: 1993 | C33: Common Size BS
A35: Current assets
A36: Cash and cash equivalent | B36: 50337 | C36: =B36/$B$45 -> 0.01775394
A37: Accounts receivable | B37: 685962 | C37: =B37/$B$45 -> 0.24193989
A38: Inventory | B38: 823181 | C38: =B38/$B$45 -> 0.29033725
A39: Prepaid expenses and deposits | B39: 240482 | C39: =B39/$B$45 -> 0.084818383
A40: Total current assets | B40: 1799962 | C40: =B40/$B$45 -> 0.63484946
A41: Property and equipment, net | B41: 638503 | C41: =B41/$B$45 -> 0.22520102
A43: Other assets, net | B43: 396793 | C43: =B43/$B$45 -> 0.13994952
A45: Total | B45: 2835258 | C45: =B45/$B$45 -> 1
A49: Liabilities and Stockholders’ Equity | B49: 1993
A51: Current liabilities
A52: Accounts payable | B52: 1946739 | C52: =B52/$B$64 -> 0.68661794
A53: Accrued wages, benefits, taxes | B53: 413597 | C53: =B53/$B$64 -> 0.14587632
A54: Other accrued liabilities | B54: 256854 | C54: =B54/$B$64 -> 0.090592814
A55: Deferred revenue (Advance received) | B55: 1628506 | C55: =B55/$B$64 -> 0.57437665
A56: Total current liabilities | B56: 4245696 | C56: =B56/$B$64 -> 1.4974637
A58: Note payable | B58: 1888139 | C58: =B58/$B$64 -> 0.66594962
A60: Other liabilities | B60: 73226 | C60: =B60/$B$64 -> 0.025826927
A62: Total stockholders’ equity (deficiency in assets) | B62: -3371803 | C62: =B62/$B$64 -> -1.1892403
A64: Total | B64: 2835258 | C64: =B64/$B$64 -> 1
...

Sheet Exhibit 8
A1: Exhibit 8 Comparable Public Companies
A3: Recent Performance ($m) | B3: 1994 | C3: 1993 | D3: 1992
A5: FY Revenues | B5: 827 | C5: 617.2 | D5: 408.4
A6: FY Net Income | B6: 19.5 | C6: 68.2 | D6: 5.2
A7: Market Capitalization at Calendar Year End | B7: 3320 | C7: 1419 | D7: 662
A8: Beta | B8: 1.39
A11: Recent Performance ($m) | B11: 1994 | C11: 1993 | D11: 1992
A13: FY Revenues | B13: 70.3 | C13: 49.5 | D13: 36.4
A14: FY Net Income | B14: 6.7 | C14: 3.1 | D14: -2.4
A15: Market Capitalization at Calendar Year End | B15: 364 | C15: 199 | D15: 180
A16: Beta | B16: 2.03
A19: Source: Compiled from corporate securities filings and public databases.

Sheet Exhibit 9
A1: Exhibit 9 Series B Term Sheet Proposed by AccessLine Management
A3: Securities: | B3: 2,000,000 shares of Series B Preferred Stock (“Shares”).
A5: Investors: | B5: The Shares will be offered only to “accredited investors” as defined in Regulation D under the Securities Act.
A7: Aggregate Proceeds: | B7: 16000000
A9: Price: | B9: $8.00 per Share (the “Sale Price”).
A11: Placement Agent: | B11: Morgan Stanley & Co. Incorporated (the “Placement Agent”) on a “best efforts” basis. The Company will pay in cash a placement fee equal to 5% of the aggregate offering proceeds.
A13: The capitalization of the Company giving effect to the Financing will be as follows:
A15: Name or Entity | B15: Class of Stock | C15: Number of Shares | D15: Total Percentage Ownership
A17: Existing Investorsa | B17: Common (Class A and B) | C17: 8086099 | D17: 0.53
B18: Series A Preferred | C18: 2220726 | D18: 0.15
B19: Warrants to Purchase
B20: Series A Preferred | C20: 333110 | D20: 0.02
A21: New Investors | B21: Series B Preferred | C21: 2000000 | D21: 0.13
A22: Reserved for Directors,
A23: Management & Employees | B23: Common (Class A and B) | C23: 2582047 | D23: 0.17
A25: Total | C25: 15221982 | D25: 1
A28: aIncludes 1,087,962 shares subject to options granted to Daniel R. Kranzler.

Sheet Valuation
A4: Projected Sales and income
B6: 1994 | C6: 1995 | D6: 1996 | E6: 1997 | F6: 1998 | G6: 1999 | H6: 2000
A7: Revenue | B7: 14.2 | C7: 32.5 | D7: =C7*(1+$B$15) -> 51.692597 | E7: =D7*(1+$B$15) -> 82.219219 | F7: =E7*(1+$B$15) -> 130.77308 | G7: 208 | H7: =G7*(1+0.05) -> 218.4
A8: Revenue | B8: 14.2 | C8: 32.5 | D8: =C8*(1+$B$15) -> 51.692597 | E8: =D8*(1+$B$15) -> 82.219219 | F8: =E8*(1+$B$15) -> 130.77308 | G8: =F8*(1+$B$15) -> 208 | H8: =G8*(1+0.05) -> 218.4
A9: PAT as % of revenue | B9: 0 | C9: 0 | D9: 0 | E9: 0.075 | F9: 0.15 | G9: 0.22 | H9: 0.22
A10: PAT | B10: =B7*B9 -> 0 | C10: =C7*C9 -> 0 | D10: =D7*D9 -> 0 | E10: =E7*E9 -> 6.1664414 | F10: =F7*F9 -> 19.615962 | G10: =G7*G9 -> 45.76 | H10: =H7*H9 -> 48.048
A12: CAGR calculation
A13: Ending value / beginning value | B13: =G7/C7 -> 6.4
A14: 1/no. of years | B14: =1/4 -> 0.25
A15: [(Ending value / beginning value)^(1-No.of years)]-1 | B15: =(B13^B14)-1 -> 0.59054146
A17: Comparable multiples
B18: 3Com | E18: Boston Tech
A19: Recent Performance ($m) | B19: 1994 | C19: 1993 | D19: 1992 | E19: 1994 | F19: 1993 | G19: 1992
A21: FY Revenues | B21: 827 | C21: 617.2 | D21: 408.4 | E21: 70.3 | F21: 49.5 | G21: 36.4
A22: FY Net Income | B22: 19.5 | C22: 68.2 | D22: 5.2 | E22: 6.7 | F22: 3.1 | G22: -2.4
A23: Market Capitalization at Calendar Year End | B23: 3320 | C23: 1419 | D23: 662 | E23: 364 | F23: 199 | G23: 180
A24: Beta | B24: 1.39 | E24: 2.03 | H24: =AVERAGE(B24:G24) -> 1.71
A26: M.Cap to sales | B26: =B23/B21 -> 4.0145103 | C26: =C23/C21 -> 2.2990927 | D26: =D23/D21 -> 1.6209598 | E26: =E23/E21 -> 5.1778094 | F26: =F23/F21 -> 4.020202 | G26: =G23/G21 -> 4.9450549 | H26: =AVERAGE(B26:G26) -> 3.6796049
A27: Average (M.cap to sales) | D27: =AVERAGE(B26:D26) -> 2.6448543 | G27: =AVERAGE(E26:G26) -> 4.7143555
A28: M.Cap to net income | B28: =B23/B22 -> 170.25641 | C28: =C23/C22 -> 20.806452 | D28: =D23/D22 -> 127.30769 | E28: =E23/E22 -> 54.328358 | F28: =F23/F22 -> 64.193548 | H28: =AVERAGE(B28:G28) -> 87.378492
A29: Average (M.cap to net income) | D29: =AVERAGE(B28:D28) -> 106.12352 | G29: =AVERAGE(E28:G28) -> 59.260953
B32: 1994 | C32: 1995 | D32: 1996 | E32: 1997 | F32: 1998 | G32: 1999
A33: Valuation as per revenue multiple | B33: =$H$26*B7 -> 52.250389 | C33: =$H$26*C7 -> 119.58716 | D33: =$H$26*D7 -> 190.20833 | E33: =$H$26*E7 -> 302.53424 | F33: =$H$26*F7 -> 481.19325 | G33: =$H$26*G7 -> 765.35781
A34: Valuation as per net income multiple (without negative multiples) | B34: =$H$28*B10 -> 0 | C34: =$H$28*C10 -> 0 | D34: =$H$28*D10 -> 0 | E34: =$H$28*E10 -> 538.81435 | F34: =$H$28*F10 -> 1714.0131 | G34: =$H$28*G10 -> 3998.4398
A36: VCs' value expectations
A37: Series B investment | B37: 16
A38: Investor value @ IRR | B38: 0.6
A39: Expected value after year | E39: 2 | F39: 3 | G39: 4
A40: Using revenue multiple base
A41: Investors' expected value | E41: =$B$37*(1+$B$38)^E39 -> 40.96 | F41: =$B$37*(1+$B$38)^F39 -> 65.536 | G41: =$B$37*(1+$B$38)^G39 -> 104.8576
A42: Investors' stake now | E42: =E41/E33 -> 0.13538963 | F42: =F41/F33 -> 0.13619476 | G42: =G41/G33 -> 0.13700468
A43: Firm value today (Pre-money) | E43: =($B$37/E42) -> 118.17744 | F43: =($B$37/F42) -> 117.47882 | G43: =($B$37/G42) -> 116.78433
A44: Price per share today (Pre-money) | E44: =E43/('Exhibit 6'!$C$8/1000000) -> 9.125737 | F44: =F43/('Exhibit 6'!$C$8/1000000) -> 9.0717894 | G44: =G43/('Exhibit 6'!$C$8/1000000) -> 9.0181607
A45: Firm value today (Post-money) | E45: =E43+$B$37 -> 134.17744 | F45: =F43+$B$37 -> 133.47882 | G45: =G43+$B$37 -> 132.78433
A46: Price per share today (Post-money) | E46: =E45/(('Exhibit 6'!$C$8/1000000)+2) -> 8.9751358 | F46: =F45/(('Exhibit 6'!$C$8/1000000)+2) -> 8.9284053 | G46: =G45/(('Exhibit 6'!$C$8/1000000)+2) -> 8.8819511
A48: Using net income multiple
A49: Investors' expected value | E49: =$B$37*(1+$B$38)^E39 -> 40.96 | F49: =$B$37*(1+$B$38)^F39 -> 65.536 | G49: =$B$37*(1+$B$38)^G39 -> 104.8576
A50: Investors' stake now | E50: =E49/E34 -> 0.076018762 | F50: =F49/F34 -> 0.038235413 | G50: =G49/G34 -> 0.026224629
A51: Firm value today (Pre-money) | E51: =($B$37/E50) -> 210.47436 | F51: =($B$37/F50) -> 418.46024 | G51: =($B$37/G50) -> 610.1135
A52: Price per share today (Pre-money) | E52: =E51/('Exhibit 6'!$C$8/1000000) -> 16.252964 | F52: =F51/('Exhibit 6'!$C$8/1000000) -> 32.313767 | G52: =G51/('Exhibit 6'!$C$8/1000000) -> 47.113353
...

Sheet Summary
I4: Series A price | J4: + | K4: Warrant price | L4: = | M4: unit price
A5: Valuation | I5: X | J5: + | K5: Y | M5: 7
A6: Revenue multiples based ($mn.) | B6: =Valuation!B33 -> 52.250389 | C6: =Valuation!C33 -> 119.58716 | D6: =Valuation!D33 -> 190.20833 | E6: =Valuation!E33 -> 302.53424 | F6: =Valuation!F33 -> 481.19325 | G6: =Valuation!G33 -> 765.35781 | I6: =K9 -> 6.0869565 | J6: + | K6: =M6-I6 -> 0.91304348 | M6: 7
A7: PPS today (Post-Money) | E7: =Valuation!E44 -> 9.125737 | F7: =Valuation!F44 -> 9.0717894 | G7: =Valuation!G44 -> 9.0181607
A8: PPS today (Pre-Money) | E8: =Valuation!E46 -> 8.9751358 | F8: =Valuation!F46 -> 8.9284053 | G8: =Valuation!G46 -> 8.8819511
J9: Share price | K9: =(2.5/2.875)*7 -> 6.0869565 | L9: =(2.22/(2.22+0.333))*7 -> 6.0869565
A10: Income multiples based ($mn.) | E10: =Valuation!E34 -> 538.81435 | F10: =Valuation!F34 -> 1714.0131 | G10: =Valuation!G34 -> 3998.4398
A11: PPS today (Post-Money) | E11: =Valuation!E52 -> 16.252964 | F11: =Valuation!F52 -> 32.313767 | G11: =Valuation!G52 -> 47.113353
A12: PPS today (Pre-Money) | E12: =Valuation!E54 -> 15.148882 | F12: =Valuation!F54 -> 29.061068 | G12: =Valuation!G54 -> 41.880765
A14: DCF value (Post Money) | G14: =Valuation!$C$80 -> 139.76971
A15: PPS today (Post-Money) | G15: =Valuation!$C$79 -> 12.028636
A16: PPS today (Pre-Money) | G16: =Valuation!$C$81 -> 10.793106

Sheet Warrant-B-S
A2: Warrant - Series A | D2: Warrant - Series B (Apex)
A3: Number of shares | B3: 2220000 | D3: Number of shares | E3: 2000000
A4: Number of warrants | B4: =B3*0.15 -> 333000 | D4: Number of warrants | E4: =E3*0.7 -> 1400000
A5: Calculated stock price | B5: 6.56 | D5: Calculated stock price | E5: 5.93 | F5: (Calculated using trial and error method)
A6: Exercise price | B6: 7 | D6: Exercise price | E6: 10
A7: Risk-free rate | B7: 0.071 | D7: Risk-free rate | E7: 0.071
A8: Expiration (year) | B8: 5 | D8: Expiration (year) | E8: 10
A9: Standard deviation | B9: 0.425 | D9: Standard deviation | E9: 0.425
A10: Dividend yield (Value loss) | D10: Dividend yield (Value loss)
A13: Output Area: | D13: Output Area:
A16: d1 | B16: =((((LN($B$5/$B$6))+(($B$7+(POWER($B$9,2)/2))*($B$8/12))))/($B$9*SQRT(($B$8/12)))) -> 0.0083619827 | D16: d1 | E16: =((((LN($B$5/$B$6))+(($B$7+(POWER($B$9,2)/2))*($B$8/12))))/($B$9*SQRT(($B$8/12)))) -> 0.0083619827
A17: d2 | B17: =$B$16-$B$9*SQRT($B$8/12) -> -0.26597434 | D17: d2 | E17: =$B$16-$B$9*SQRT($B$8/12) -> -0.26597434
A18: N(d1) | B18: =NORMSDIST(B16) -> 0.50333591 | D18: N(d1) | E18: =NORMSDIST(E16) -> 0.50333591
A19: N(d2) | B19: =NORMSDIST(B17) -> 0.39512949 | D19: N(d2) | E19: =NORMSDIST(E17) -> 0.39512949
A21: Call | B21: =($B$5*$B$18)-(($B$6*EXP(-$B$7*($B$8/12))*$B$19)) -> 0.61660342 | D21: Call | E21: =($B$5*$B$18)-(($B$6*EXP(-$B$7*($B$8/12))*$B$19)) -> 0.61660342
A22: Put | B22: =($B$6*EXP(-$B$7*($B$8/12)))+$B$21-$B$5 -> 0.85255321 | D22: Put | E22: =($B$6*EXP(-$B$7*($B$8/12)))+$B$21-$B$5 -> 0.85255321
A26: Calculating d1 | D26: Calculating d1
A28: ln(s/e) | B28: =LN(B5/B6) -> -0.064919546 | D28: ln(s/e) | E28: =LN(E5/E6) -> -0.52256088
A29: (r-d)+(variance/2) | B29: =(B7-B10)+((B9^2)/2) -> 0.1613125 | D29: (r-d)+(variance/2) | E29: =(E7-E10)+((E9^2)/2) -> 0.1613125
A30: t | B30: =B8 -> 5 | D30: t | E30: =E8 -> 10
A31: SD * route t. | B31: =B9*SQRT(B30) -> 0.95032889 | D31: SD * route t. | E31: =E9*SQRT(E30) -> 1.343968
A32: d1 | B32: =(B28+(B29*B30))/B31 -> 0.78040662 | D32: d1 | E32: =(E28+(E29*E30))/E31 -> 0.81145095
A34: Calculating d2 | B34: =B32-B31 -> -0.16992227 | D34: Calculating d2 | E34: =E32-E31 -> -0.53251705
A36: N(d1) | B36: =NORMSDIST(B32) -> 0.78242421 | D36: N(d1) | E36: =NORMSDIST(E32) -> 0.79144663
A37: N(d2) | B37: =NORMSDIST(B34) -> 0.43253563 | D37: N(d2) | E37: =NORMSDIST(E34) -> 0.29718397
A39: Value of call | D39: Value of call
A40: S*d^-dt N(d1) | B40: =(B5*(EXP(-B10*B8)))*B36 -> 5.1327028 | D40: S*d^-dt N(d1) | E40: =(E5*(EXP(-E10*E8)))*E36 -> 4.6932785
A41: e^-rt | B41: =1/(EXP(B7*B30)) -> 0.70117344 | D41: e^-rt | E41: =1/(EXP(E7*E30)) -> 0.4916442
A42: E x e^-rt | B42: =B6*B41 -> 4.9082141 | D42: E x e^-rt | E42: =E6*E41 -> 4.916442
A43: N (d2) | B43: =B37 -> 0.43253563 | D43: N (d2) | E43: =E37 -> 0.29718397
A44: (E x e^-rt)*N (d2) | B44: =B42*B43 -> 2.1229775 | D44: (E x e^-rt)*N (d2) | E44: =E42*E43 -> 1.4610877
A45: Value of call | B45: =B40-B44 -> 3.0097253 | D45: Value of call | E45: =E40-E44 -> 3.2321908
A47: Dilution | B47: =('Dilution effect'!C11-'Dilution effect'!C6)/'Dilution effect'!C11 -> 0.97362983 | D47: Dilution | E47: =('Dilution effect'!K11-'Dilution effect'!K8)/'Dilution effect'!K11 -> 0.91577418
A48: Warrant price | B48: =B45*B47 -> 2.9303584 | D48: Warrant price | E48: =E45*E47 -> 2.9599568
A49: 15% of warrant price | B49: =B48*0.15 -> 0.43955376 | D49: 70% of warrant price | E49: =E48*0.7 -> 2.0719698
B51: =B5+B49 -> 6.9995538 | E51: =E5+E49 -> 8.0019698

Sheet Dilution effect
A1: Exhibit 6 Access Series A Term Sheet: June 4, 1994 (Adjusted to actual)
C2: Series A | G2: Series B (Accessline) | K2: Series B (Apex)
A3: Name or Entity | B3: Class of Stock | C3: Number of Shares | D3: Total Percentage Ownership | E3: Value of shares | F3: Percentage ownership (Value) | G3: Number of Shares | H3: Total Percentage Ownership | I3: Value of shares | J3: Percentage ownership (Value) | K3: Number of Shares | L3: Total Percentage Ownership | M3: Value of shares | N3: Percentage ownership (Value)
A4: Existing Investorsb | B4: Common (Class A and B) | C4: 7931060 | D4: =C4/$C$11 -> 0.62805821 | E4: =C4*7 -> 55517420 | F4: =E4/$E$11 -> 0.62805821 | G4: 8086099 | H4: =G4/$G$11 -> 0.53121201 | I4: =G4*8 -> 64688792 | J4: =I4/$I$11 -> 0.53121201 | K4: 8086099 | L4: =K4/$G$11 -> 0.53121201 | M4: =K4*8 -> 64688792 | N4: =M4/$M$11 -> 0.53121201 | T4: =G4+157677 -> 8243776
A5: New Investors (Series A) | B5: Preferred stock | C5: 2220000 | D5: =C5/$C$11 -> 0.17580112 | E5: =C5*7 -> 15540000 | F5: =E5/$E$11 -> 0.17580112 | G5: 2220726 | H5: =G5/$G$11 -> 0.14588942 | I5: =G5*8 -> 17765808 | J5: =I5/$I$11 -> 0.14588942 | K5: 2220726 | L5: =K5/$G$11 -> 0.14588942 | M5: =K5*8 -> 17765808 | N5: =M5/$M$11 -> 0.14588942 | T5: =C10+643600 -> 2787446
B6: Warrants | C6: =C5*0.15 -> 333000 | D6: =C6/$C$11 -> 0.026370168 | E6: =C6*7 -> 2331000 | F6: =E6/$E$11 -> 0.026370168 | G6: =G5*0.15 -> 333108.9 | H6: =G6/$G$11 -> 0.021883413 | I6: =G6*8 -> 2664871.2 | J6: =I6/$I$11 -> 0.021883413 | K6: =K5*0.15 -> 333108.9 | L6: =K6/$G$11 -> 0.021883413 | M6: =K6*8 -> 2664871.2 | N6: =M6/$M$11 -> 0.021883413
A7: New Investors (Series B) | B7: Preferred stock | D7: =C7/$C$11 -> 0 | F7: =E7/$E$11 -> 0 | G7: 2000000 | H7: =G7/$G$11 -> 0.13138894 | I7: =G7*8 -> 16000000 | J7: =I7/$I$11 -> 0.13138894 | K7: 2000000 | L7: =K7/$G$11 -> 0.13138894 | M7: =K7*8 -> 16000000 | N7: =M7/$M$11 -> 0.13138894
B8: Warrants | D8: =C8/$C$11 -> 0 | F8: =E8/$E$11 -> 0 | H8: =G8/$G$11 -> 0 | I8: =G8*8 -> 0 | J8: =I8/$I$11 -> 0 | K8: 1400000 | L8: =K8/$G$11 -> 0.091972261 | M8: 0 | N8: =M8/$M$11 -> 0
D9: =C9/$C$11 -> 0 | F9: =E9/$E$11 -> 0 | H9: =G9/$G$11 -> 0 | J9: =I9/$I$11 -> 0 | L9: =K9/$G$11 -> 0 | N9: =M9/$M$11 -> 0
A10: Reserved for Management and Employeesc | B10: Common (Class A and B) | C10: 2143846 | D10: =C10/$C$11 -> 0.16977051 | E10: =C10*7 -> 15006922 | F10: =E10/$E$11 -> 0.16977051 | G10: 2582047 | H10: =G10/$G$11 -> 0.16962621 | I10: =G10*8 -> 20656376 | J10: =I10/$I$11 -> 0.16962621 | K10: 2582047 | L10: =K10/$G$11 -> 0.16962621 | M10: =K10*8 -> 20656376 | N10: =M10/$M$11 -> 0.16962621
A11: Total | C11: =SUM(C4:C10) -> 12627906 | D11: =SUM(D4:D10) -> 1 | E11: =SUM(E4:E10) -> 88395342 | F11: =SUM(F4:F10) -> 1 | G11: =SUM(G4:G10) -> 15221981 | H11: =SUM(H4:H10) -> 1 | I11: =SUM(I4:I10) -> 1.2177585e+08 | J11: =SUM(J4:J10) -> 1 | ... N11: =SUM(N4:N10) -> 1
A14: aWhile the term sheet was prepared assuming the sale of 2.5 million shares, 2.22 million shares were actually sold. | K14: =(K11-K8)/K11 -> 0.91577418
A15: bIncludes 157,677 shares issued as part of the Fuller Research & Development Company merger, 389,820 shares issued pursuant to restricted stock grants and 1,087,962 shares subject to options granted to Daniel R. Kranzler.
A16: cExcludes 643,600 shares reserved for future grant.
